Workbook

Sheet Lisez-moi
A1: COTE — base de suivi des cotes
A3: Généré le | B3: 46310
A4: Dernier relevé | B4: 46310
A5: Dashboard | B5: https://mattchampavier-ui.github.io/cote-auto/
A7: Fonctionnement | B7: Ce fichier est régénéré automatiquement à chaque relevé (chaque lundi et le 1er du mois) à partir de tout l'historique.
B8: Il est aussi joint au récap mensuel par mail. Toute modification faite à la main ici sera écrasée : enregistre une copie pour annoter.
A10: Onglets
A11: Analyse du mois | B11: Situation actuelle de chaque véhicule : score, signal, prix, tendances, offre, ventes. Indicateurs clés en haut.
A12: Historique mensuel | B12: Une ligne par véhicule et par mois (dernier relevé du mois). Variations vs mois précédent calculées par formule.
A13: Médianes par mois | B13: Tableau croisé véhicule × mois des prix médians (formules sur l'onglet Historique mensuel).
A14: Indice base 100 | B14: Évolution de la médiane depuis le premier mois suivi (100 = premier mois), avec graphique.
A15: Relevés | B15: Tous les relevés bruts, y compris l'amorce manuelle de septembre 2026.
A16: Annonces | B16: Chaque annonce avec tout ce que fournit LeBonCoin : version et finition exactes, prix, ancien prix, estimation de prix LeBonCoin (min/max, positionnement), km, année, mise en circulation, carburant, boîte, puissance, couleur, entretien, historique, vendeur pro/particulier, localisation, photos, description ; durée en ligne et baisses de prix.
A17: Historique des prix | B17: Chaque prix relevé pour chaque annonce, avec l'évolution d'un relevé à l'autre.
A18: Par année-modèle | B18: Prix moyen, plus bas, plus haut et km moyen par véhicule et par année-modèle (annonces en vente).
A19: Par kilométrage | B19: Mêmes indicateurs par tranche de kilométrage : mesure la décote liée au km.
A20: Bonnes affaires | B20: Annonces du dernier relevé au moins 15 % sous la cote attendue pour leur kilométrage.
A21: Véhicules | B21: Liste des véhicules suivis ou retirés et leurs critères de recherche.
A23: Définitions
A24: Médiane | B24: Prix médian des annonces retenues (après filtres : pièces, épaves, autres versions, doublons, prix aberrants).
A25: Cote à km réf. | B25: Prix attendu à un kilométrage de référence fixe (régression prix/km) : compare les mois sans biais de kilométrage.
A26: Position fourchette | B26: 0 % = au plancher, 100 % = au plafond de prix observé (ou saisi pendant les 3 premiers mois).
A27: Score | B27: Sur 100 : rareté 20 %, désirabilité 20 %, « dernier de » 10 %, proximité du plancher 20 %, momentum 15 %, marché 15 %.
A28: Ventes | B28: Annonces disparues entre deux relevés. Une annonce peut aussi être retirée sans vente : c'est une estimation.
A29: Avertissement | B29: Outil de suivi de marché, pas un conseil d'achat.

Sheet Analyse du mois
A1: Analyse au 15/10/2026
A3: Véhicules suivis | C3: Score moyen | E3: Annonces actives
A4: =COUNTA(A9:A24) | C4: =IFERROR(AVERAGEIF(N9:N24,">0",C9:C24),0) | E4: =SUM(N9:N24)
A5: Ventes sur 30 jours | C5: Signaux d'achat | E5: Bonnes affaires
A6: =SUM(O9:O24) | C6: =COUNTIF(D9:D24,"Signal d'achat") | E6: =SUM(Q9:Q24)
A8: Véhicule | B8: Catégorie | C8: Score /100 | D8: Signal | E8: Médiane | F8: Plancher | G8: Plafond | H8: Position fourchette | I8: Tendance 1 mois | J8: Tendance 3 mois | K8: Tendance 12 mois | L8: Cote à km réf. | M8: Km réf. | N8: Annonces | O8: Vendues (30 j) | P8: Délai de vente | Q8: Bonnes affaires | R8: Rareté | S8: Désirabilité | T8: Dernier de | U8: Proximité plancher | V8: Momentum | W8: Marché | X8: Dernier relevé | Y8: LeBonCoin | Z8: Part de pros (en vente) | AA8: Part avec carnet d'entretien | AB8: Écart moyen vs estimation LBC | AC8: Jours en ligne moyens
A9: Peugeot 208 GTi 30th | B9: Hot-hatch récente à tirage limité | C9: 70.2 | D9: Signal d'achat | E9: 15900 | F9: 12000 | G9: 24000 | H9: =IF(AND(ISNUMBER(E9),ISNUMBER(F9),ISNUMBER(G9),G9>F9),(E9-F9)/(G9-F9),"") | L9: 15360 | M9: 100000 | N9: 11 | O9: 2 | P9: 61 | Q9: 2 | R9: 85 | S9: 80 | T9: 65 | U9: 68 | V9: 50 | W9: 65 | X9: 46310 | Y9: Voir | Z9: =IFERROR(COUNTIFS(Annonces!$A$2:$A$701,$A9,Annonces!$E$2:$E$701,"En vente",Annonces!$AF$2:$AF$701,"Pro")/COUNTIFS(Annonces!$A$2:$A$701,$A9,Annonces!$E$2:$E$701,"En vente",Annonces!$AF$2:$AF$701,"<>"),"") | AA9: =IFERROR(COUNTIFS(Annonces!$A$2:$A$701,$A9,Annonces!$E$2:$E$701,"En vente",Annonces!$AD$2:$AD$701,"*arnet*")/COUNTIFS(Annonces!$A$2:$A$701,$A9,Annonces!$E$2:$E$701,"En vente",Annonces!$AD$2:$AD$701,"<>"),"") | AB9: =IFERROR(AVERAGEIFS(Annonces!$R$2:$R$701,Annonces!$A$2:$A$701,$A9,Annonces!$E$2:$E$701,"En vente"),"") | AC9: =IFERROR(AVERAGEIFS(Annonces!$J$2:$J$701,Annonces!$A$2:$A$701,$A9,Annonces!$E$2:$E$701,"En vente"),"")
A10: Porsche 911 997 Carrera S | B10: Sportive iconique | C10: 68.9 | D10: Signal d'achat | E10: 54990 | F10: 40000 | G10: 75000 | H10: =IF(AND(ISNUMBER(E10),ISNUMBER(F10),ISNUMBER(G10),G10>F10),(E10-F10)/(G10-F10),"") | L10: 55870 | M10: 100000 | N10: 39 | O10: 0 | Q10: 3 | R10: 40 | S10: 90 | T10: 90 | U10: 57 | V10: 50 | W10: 100 | X10: 46310 | Y10: Voir | Z10: =IFERROR(COUNTIFS(Annonces!$A$2:$A$701,$A10,Annonces!$E$2:$E$701,"En vente",Annonces!$AF$2:$AF$701,"Pro")/COUNTIFS(Annonces!$A$2:$A$701,$A10,Annonces!$E$2:$E$701,"En vente",Annonces!$AF$2:$AF$701,"<>"),"") | AA10: =IFERROR(COUNTIFS(Annonces!$A$2:$A$701,$A10,Annonces!$E$2:$E$701,"En vente",Annonces!$AD$2:$AD$701,"*arnet*")/COUNTIFS(Annonces!$A$2:$A$701,$A10,Annonces!$E$2:$E$701,"En vente",Annonces!$AD$2:$AD$701,"<>"),"") | AB10: =IFERROR(AVERAGEIFS(Annonces!$R$2:$R$701,Annonces!$A$2:$A$701,$A10,Annonces!$E$2:$E$701,"En vente"),"") | AC10: =IFERROR(AVERAGEIFS(Annonces!$J$2:$J$701,Annonces!$A$2:$A$701,$A10,Annonces!$E$2:$E$701,"En vente"),"")
A11: Peugeot 205 GTI | B11: Hot-hatch icône des années 80 | C11: 67.3 | D11: À surveiller | E11: 15450 | F11: 13125 | G11: 20675 | H11: =IF(AND(ISNUMBER(E11),ISNUMBER(F11),ISNUMBER(G11),G11>F11),(E11-F11)/(G11-F11),"") | L11: 16890 | M11: 190000 | N11: 40 | O11: 0 | Q11: 5 | R11: 45 | S11: 85 | T11: 50 | U11: 69 | V11: 50 | W11: 100 | X11: 46310 | Y11: Voir | Z11: =IFERROR(COUNTIFS(Annonces!$A$2:$A$701,$A11,Annonces!$E$2:$E$701,"En vente",Annonces!$AF$2:$AF$701,"Pro")/COUNTIFS(Annonces!$A$2:$A$701,$A11,Annonces!$E$2:$E$701,"En vente",Annonces!$AF$2:$AF$701,"<>"),"") | AA11: =IFERROR(COUNTIFS(Annonces!$A$2:$A$701,$A11,Annonces!$E$2:$E$701,"En vente",Annonces!$AD$2:$AD$701,"*arnet*")/COUNTIFS(Annonces!$A$2:$A$701,$A11,Annonces!$E$2:$E$701,"En vente",Annonces!$AD$2:$AD$701,"<>"),"") | AB11: =IFERROR(AVERAGEIFS(Annonces!$R$2:$R$701,Annonces!$A$2:$A$701,$A11,Annonces!$E$2:$E$701,"En vente"),"") | AC11: =IFERROR(AVERAGEIFS(Annonces!$J$2:$J$701,Annonces!$A$2:$A$701,$A11,Annonces!$E$2:$E$701,"En vente"),"")
A12: Peugeot 206 RC | B12: Hot-hatch youngtimer 2000-2005 | C12: 65.9 | D12: À surveiller | E12: 9000 | F12: 6500 | G12: 13500 | H12: =IF(AND(ISNUMBER(E12),ISNUMBER(F12),ISNUMBER(G12),G12>F12),(E12-F12)/(G12-F12),"") | L12: 11050 | M12: 150000 | N12: 40 | O12: 0 | Q12: 5 | R12: 45 | S12: 70 | T12: 75 | U12: 64 | V12: 50 | W12: 100 | X12: 46310 | Y12: Voir | Z12: =IFERROR(COUNTIFS(Annonces!$A$2:$A$701,$A12,Annonces!$E$2:$E$701,"En vente",Annonces!$AF$2:$AF$701,"Pro")/COUNTIFS(Annonces!$A$2:$A$701,$A12,Annonces!$E$2:$E$701,"En vente",Annonces!$AF$2:$AF$701,"<>"),"") | AA12: =IFERROR(COUNTIFS(Annonces!$A$2:$A$701,$A12,Annonces!$E$2:$E$701,"En vente",Annonces!$AD$2:$AD$701,"*arnet*")/COUNTIFS(Annonces!$A$2:$A$701,$A12,Annonces!$E$2:$E$701,"En vente",Annonces!$AD$2:$AD$701,"<>"),"") | AB12: =IFERROR(AVERAGEIFS(Annonces!$R$2:$R$701,Annonces!$A$2:$A$701,$A12,Annonces!$E$2:$E$701,"En vente"),"") | AC12: =IFERROR(AVERAGEIFS(Annonces!$J$2:$J$701,Annonces!$A$2:$A$701,$A12,Annonces!$E$2:$E$701,"En vente"),"")
A13: Renault Twingo 1 découvrable | B13: Citadine iconique, variante toit ouvrant | C13: 65.5 | D13: À surveiller | E13: 3000 | F13: 1500 | G13: 6500 | H13: =IF(AND(ISNUMBER(E13),ISNUMBER(F13),ISNUMBER(G13),G13>F13),(E13-F13)/(G13-F13),"") | L13: 3530 | M13: 150000 | N13: 37 | O13: 0 | Q13: 5 | R13: 55 | S13: 65 | T13: 50 | U13: 70 | V13: 50 | W13: 100 | X13: 46310 | Y13: Voir | Z13: =IFERROR(COUNTIFS(Annonces!$A$2:$A$701,$A13,Annonces!$E$2:$E$701,"En vente",Annonces!$AF$2:$AF$701,"Pro")/COUNTIFS(Annonces!$A$2:$A$701,$A13,Annonces!$E$2:$E$701,"En vente",Annonces!$AF$2:$AF$701,"<>"),"") | AA13: =IFERROR(COUNTIFS(Annonces!$A$2:$A$701,$A13,Annonces!$E$2:$E$701,"En vente",Annonces!$AD$2:$AD$701,"*arnet*")/COUNTIFS(Annonces!$A$2:$A$701,$A13,Annonces!$E$2:$E$701,"En vente",Annonces!$AD$2:$AD$701,"<>"),"") | AB13: =IFERROR(AVERAGEIFS(Annonces!$R$2:$R$701,Annonces!$A$2:$A$701,$A13,Annonces!$E$2:$E$701,"En vente"),"") | AC13: =IFERROR(AVERAGEIFS(Annonces!$J$2:$J$701,Annonces!$A$2:$A$701,$A13,Annonces!$E$2:$E$701,"En vente"),"")
A14: Honda S2000 | B14: Roadster japonais culte | C14: 65.2 | D14: À surveiller | E14: 23900 | F14: 14900 | G14: 28950 | H14: =IF(AND(ISNUMBER(E14),ISNUMBER(F14),ISNUMBER(G14),G14>F14),(E14-F14)/(G14-F14),"") | L14: 22870 | M14: 140000 | N14: 39 | O14: 0 | Q14: 5 | R14: 50 | S14: 85 | T14: 85 | U14: 36 | V14: 50 | W14: 100 | X14: 46310 | Y14: Voir | Z14: =IFERROR(COUNTIFS(Annonces!$A$2:$A$701,$A14,Annonces!$E$2:$E$701,"En vente",Annonces!$AF$2:$AF$701,"Pro")/COUNTIFS(Annonces!$A$2:$A$701,$A14,Annonces!$E$2:$E$701,"En vente",Annonces!$AF$2:$AF$701,"<>"),"") | AA14: =IFERROR(COUNTIFS(Annonces!$A$2:$A$701,$A14,Annonces!$E$2:$E$701,"En vente",Annonces!$AD$2:$AD$701,"*arnet*")/COUNTIFS(Annonces!$A$2:$A$701,$A14,Annonces!$E$2:$E$701,"En vente",Annonces!$AD$2:$AD$701,"<>"),"") | AB14: =IFERROR(AVERAGEIFS(Annonces!$R$2:$R$701,Annonces!$A$2:$A$701,$A14,Annonces!$E$2:$E$701,"En vente"),"") | AC14: =IFERROR(AVERAGEIFS(Annonces!$J$2:$J$701,Annonces!$A$2:$A$701,$A14,Annonces!$E$2:$E$701,"En vente"),"")
A15: Renault Clio II RS (172/182 ch) | B15: Hot-hatch youngtimer 2000-2005 | C15: 62.8 | D15: À surveiller | E15: 10195 | F15: 5000 | G15: 17000 | H15: =IF(AND(ISNUMBER(E15),ISNUMBER(F15),ISNUMBER(G15),G15>F15),(E15-F15)/(G15-F15),"") | L15: 10520 | M15: 160000 | N15: 36 | O15: 0 | Q15: 5 | R15: 40 | S15: 75 | T15: 60 | U15: 57 | V15: 50 | W15: 100 | X15: 46310 | Y15: Voir | Z15: =IFERROR(COUNTIFS(Annonces!$A$2:$A$701,$A15,Annonces!$E$2:$E$701,"En vente",Annonces!$AF$2:$AF$701,"Pro")/COUNTIFS(Annonces!$A$2:$A$701,$A15,Annonces!$E$2:$E$701,"En vente",Annonces!$AF$2:$AF$701,"<>"),"") | AA15: =IFERROR(COUNTIFS(Annonces!$A$2:$A$701,$A15,Annonces!$E$2:$E$701,"En vente",Annonces!$AD$2:$AD$701,"*arnet*")/COUNTIFS(Annonces!$A$2:$A$701,$A15,Annonces!$E$2:$E$701,"En vente",Annonces!$AD$2:$AD$701,"<>"),"") | AB15: =IFERROR(AVERAGEIFS(Annonces!$R$2:$R$701,Annonces!$A$2:$A$701,$A15,Annonces!$E$2:$E$701,"En vente"),"") | AC15: =IFERROR(AVERAGEIFS(Annonces!$J$2:$J$701,Annonces!$A$2:$A$701,$A15,Annonces!$E$2:$E$701,"En vente"),"")
A16: Peugeot 306 S16 | B16: Hot-hatch youngtimer 1990-2000 | C16: 61.9 | D16: À surveiller | E16: 9500 | F16: 6800 | G16: 15000 | H16: =IF(AND(ISNUMBER(E16),ISNUMBER(F16),ISNUMBER(G16),G16>F16),(E16-F16)/(G16-F16),"") | L16: 11490 | M16: 180000 | N16: 33 | O16: 0 | Q16: 5 | R16: 40 | S16: 65 | T16: 50 | U16: 67 | V16: 50 | W16: 100 | X16: 46310 | Y16: Voir | Z16: =IFERROR(COUNTIFS(Annonces!$A$2:$A$701,$A16,Annonces!$E$2:$E$701,"En vente",Annonces!$AF$2:$AF$701,"Pro")/COUNTIFS(Annonces!$A$2:$A$701,$A16,Annonces!$E$2:$E$701,"En vente",Annonces!$AF$2:$AF$701,"<>"),"") | AA16: =IFERROR(COUNTIFS(Annonces!$A$2:$A$701,$A16,Annonces!$E$2:$E$701,"En vente",Annonces!$AD$2:$AD$701,"*arnet*")/COUNTIFS(Annonces!$A$2:$A$701,$A16,Annonces!$E$2:$E$701,"En vente",Annonces!$AD$2:$AD$701,"<>"),"") | AB16: =IFERROR(AVERAGEIFS(Annonces!$R$2:$R$701,Annonces!$A$2:$A$701,$A16,Annonces!$E$2:$E$701,"En vente"),"") | AC16: =IFERROR(AVERAGEIFS(Annonces!$J$2:$J$701,Annonces!$A$2:$A$701,$A16,Annonces!$E$2:$E$701,"En vente"),"")
A17: BMW Z3 1.9i / 2.0i | B17: Roadster youngtimer | C17: 61.9 | D17: À surveiller | E17: 10245 | F17: 9498 | G17: 12740 | H17: =IF(AND(ISNUMBER(E17),ISNUMBER(F17),ISNUMBER(G17),G17>F17),(E17-F17)/(G17-F17),"") | L17: 10900 | M17: 130000 | N17: 24 | O17: 0 | Q17: 3 | R17: 35 | S17: 65 | T17: 40 | U17: 77 | V17: 50 | W17: 100 | X17: 46310 | Y17: Voir | Z17: =IFERROR(COUNTIFS(Annonces!$A$2:$A$701,$A17,Annonces!$E$2:$E$701,"En vente",Annonces!$AF$2:$AF$701,"Pro")/COUNTIFS(Annonces!$A$2:$A$701,$A17,Annonces!$E$2:$E$701,"En vente",Annonces!$AF$2:$AF$701,"<>"),"") | AA17: =IFERROR(COUNTIFS(Annonces!$A$2:$A$701,$A17,Annonces!$E$2:$E$701,"En vente",Annonces!$AD$2:$AD$701,"*arnet*")/COUNTIFS(Annonces!$A$2:$A$701,$A17,Annonces!$E$2:$E$701,"En vente",Annonces!$AD$2:$AD$701,"<>"),"") | AB17: =IFERROR(AVERAGEIFS(Annonces!$R$2:$R$701,Annonces!$A$2:$A$701,$A17,Annonces!$E$2:$E$701,"En vente"),"") | AC17: =IFERROR(AVERAGEIFS(Annonces!$J$2:$J$701,Annonces!$A$2:$A$701,$A17,Annonces!$E$2:$E$701,"En vente"),"")
A18: Volkswagen Golf IV GTI 25th Anniversary | B18: Hot-hatch à série limitée | C18: 61 | D18: À surveiller | E18: 11000 | F18: 11000 | G18: 11000 | H18: =IF(AND(ISNUMBER(E18),ISNUMBER(F18),ISNUMBER(G18),G18>F18),(E18-F18)/(G18-F18),"") | L18: 11000 | M18: 200000 | N18: 1 | O18: 0 | Q18: 0 | R18: 70 | S18: 65 | T18: 55 | U18: 100 | V18: 50 | W18: 7 | X18: 46310 | Y18: Voir | Z18: =IFERROR(COUNTIFS(Annonces!$A$2:$A$701,$A18,Annonces!$E$2:$E$701,"En vente",Annonces!$AF$2:$AF$701,"Pro")/COUNTIFS(Annonces!$A$2:$A$701,$A18,Annonces!$E$2:$E$701,"En vente",Annonces!$AF$2:$AF$701,"<>"),"") | AA18: =IFERROR(COUNTIFS(Annonces!$A$2:$A$701,$A18,Annonces!$E$2:$E$701,"En vente",Annonces!$AD$2:$AD$701,"*arnet*")/COUNTIFS(Annonces!$A$2:$A$701,$A18,Annonces!$E$2:$E$701,"En vente",Annonces!$AD$2:$AD$701,"<>"),"") | AB18: =IFERROR(AVERAGEIFS(Annonces!$R$2:$R$701,Annonces!$A$2:$A$701,$A18,Annonces!$E$2:$E$701,"En vente"),"") | AC18: =IFERROR(AVERAGEIFS(Annonces!$J$2:$J$701,Annonces!$A$2:$A$701,$A18,Annonces!$E$2:$E$701,"En vente"),"")
A19: Porsche Boxster 987 | B19: Roadster Porsche | C19: 60.1 | D19: À surveiller | E19: 29250 | F19: 20000 | G19: 45000 | H19: =IF(AND(ISNUMBER(E19),ISNUMBER(F19),ISNUMBER(G19),G19>F19),(E19-F19)/(G19-F19),"") | L19: 32020 | M19: 80000 | N19: 40 | O19: 0 | Q19: 5 | R19: 30 | S19: 75 | T19: 40 | U19: 63 | V19: 50 | W19: 100 | X19: 46310 | Y19: Voir | Z19: =IFERROR(COUNTIFS(Annonces!$A$2:$A$701,$A19,Annonces!$E$2:$E$701,"En vente",Annonces!$AF$2:$AF$701,"Pro")/COUNTIFS(Annonces!$A$2:$A$701,$A19,Annonces!$E$2:$E$701,"En vente",Annonces!$AF$2:$AF$701,"<>"),"") | AA19: =IFERROR(COUNTIFS(Annonces!$A$2:$A$701,$A19,Annonces!$E$2:$E$701,"En vente",Annonces!$AD$2:$AD$701,"*arnet*")/COUNTIFS(Annonces!$A$2:$A$701,$A19,Annonces!$E$2:$E$701,"En vente",Annonces!$AD$2:$AD$701,"<>"),"") | AB19: =IFERROR(AVERAGEIFS(Annonces!$R$2:$R$701,Annonces!$A$2:$A$701,$A19,Annonces!$E$2:$E$701,"En vente"),"") | AC19: =IFERROR(AVERAGEIFS(Annonces!$J$2:$J$701,Annonces!$A$2:$A$701,$A19,Annonces!$E$2:$E$701,"En vente"),"")
A20: Porsche Boxster 986 | B20: Roadster d'entrée de gamme Porsche | C20: 58.4 | D20: À surveiller | E20: 19890 | F20: 15000 | G20: 27000 | H20: =IF(AND(ISNUMBER(E20),ISNUMBER(F20),ISNUMBER(G20),G20>F20),(E20-F20)/(G20-F20),"") | L20: 20520 | M20: 110000 | N20: 40 | O20: 0 | Q20: 5 | R20: 35 | S20: 70 | T20: 30 | U20: 59 | V20: 50 | W20: 100 | X20: 46310 | Y20: Voir | Z20: =IFERROR(COUNTIFS(Annonces!$A$2:$A$701,$A20,Annonces!$E$2:$E$701,"En vente",Annonces!$AF$2:$AF$701,"Pro")/COUNTIFS(Annonces!$A$2:$A$701,$A20,Annonces!$E$2:$E$701,"En vente",Annonces!$AF$2:$AF$701,"<>"),"") | AA20: =IFERROR(COUNTIFS(Annonces!$A$2:$A$701,$A20,Annonces!$E$2:$E$701,"En vente",Annonces!$AD$2:$AD$701,"*arnet*")/COUNTIFS(Annonces!$A$2:$A$701,$A20,Annonces!$E$2:$E$701,"En vente",Annonces!$AD$2:$AD$701,"<>"),"") | AB20: =IFERROR(AVERAGEIFS(Annonces!$R$2:$R$701,Annonces!$A$2:$A$701,$A20,Annonces!$E$2:$E$701,"En vente"),"") | AC20: =IFERROR(AVERAGEIFS(Annonces!$J$2:$J$701,Annonces!$A$2:$A$701,$A20,Annonces!$E$2:$E$701,"En vente"),"")
A21: Renault Mégane II RS R26 | B21: Hot-hatch à série limitée | C21: 58 | D21: À surveiller | E21: 22990 | F21: 19900 | G21: 24990 | H21: =IF(AND(ISNUMBER(E21),ISNUMBER(F21),ISNUMBER(G21),G21>F21),(E21-F21)/(G21-F21),"") | L21: 23170 | M21: 100000 | N21: 15 | O21: 5 | P21: 62 | Q21: 2 | R21: 55 | S21: 75 | T21: 50 | U21: 39 | V21: 50 | W21: 78 | X21: 46310 | Y21: Voir | Z21: =IFERROR(COUNTIFS(Annonces!$A$2:$A$701,$A21,Annonces!$E$2:$E$701,"En vente",Annonces!$AF$2:$AF$701,"Pro")/COUNTIFS(Annonces!$A$2:$A$701,$A21,Annonces!$E$2:$E$701,"En vente",Annonces!$AF$2:$AF$701,"<>"),"") | AA21: =IFERROR(COUNTIFS(Annonces!$A$2:$A$701,$A21,Annonces!$E$2:$E$701,"En vente",Annonces!$AD$2:$AD$701,"*arnet*")/COUNTIFS(Annonces!$A$2:$A$701,$A21,Annonces!$E$2:$E$701,"En vente",Annonces!$AD$2:$AD$701,"<>"),"") | AB21: =IFERROR(AVERAGEIFS(Annonces!$R$2:$R$701,Annonces!$A$2:$A$701,$A21,Annonces!$E$2:$E$701,"En vente"),"") | AC21: =IFERROR(AVERAGEIFS(Annonces!$J$2:$J$701,Annonces!$A$2:$A$701,$A21,Annonces!$E$2:$E$701,"En vente"),"")
A22: Mazda MX-5 NA | B22: Roadster youngtimer | C22: 56.1 | D22: À surveiller | E22: 11990 | F22: 8938 | G22: 13875 | H22: =IF(AND(ISNUMBER(E22),ISNUMBER(F22),ISNUMBER(G22),G22>F22),(E22-F22)/(G22-F22),"") | L22: 11470 | M22: 160000 | N22: 38 | O22: 0 | Q22: 5 | R22: 25 | S22: 75 | T22: 60 | U22: 38 | V22: 50 | W22: 100 | X22: 46310 | Y22: Voir | Z22: =IFERROR(COUNTIFS(Annonces!$A$2:$A$701,$A22,Annonces!$E$2:$E$701,"En vente",Annonces!$AF$2:$AF$701,"Pro")/COUNTIFS(Annonces!$A$2:$A$701,$A22,Annonces!$E$2:$E$701,"En vente",Annonces!$AF$2:$AF$701,"<>"),"") | AA22: =IFERROR(COUNTIFS(Annonces!$A$2:$A$701,$A22,Annonces!$E$2:$E$701,"En vente",Annonces!$AD$2:$AD$701,"*arnet*")/COUNTIFS(Annonces!$A$2:$A$701,$A22,Annonces!$E$2:$E$701,"En vente",Annonces!$AD$2:$AD$701,"<>"),"") | AB22: =IFERROR(AVERAGEIFS(Annonces!$R$2:$R$701,Annonces!$A$2:$A$701,$A22,Annonces!$E$2:$E$701,"En vente"),"") | AC22: =IFERROR(AVERAGEIFS(Annonces!$J$2:$J$701,Annonces!$A$2:$A$701,$A22,Annonces!$E$2:$E$701,"En vente"),"")
A23: Citroën Saxo VTS 16V | B23: Hot-hatch youngtimer 2000-2005 | C23: 56 | D23: À surveiller | E23: 6750 | F23: 4500 | G23: 9500 | H23: =IF(AND(ISNUMBER(E23),ISNUMBER(F23),ISNUMBER(G23),G23>F23),(E23-F23)/(G23-F23),"") | L23: 7450 | M23: 150000 | N23: 40 | O23: 0 | Q23: 5 | R23: 30 | S23: 55 | T23: 55 | U23: 55 | V23: 50 | W23: 100 | X23: 46310 | Y23: Voir | Z23: =IFERROR(COUNTIFS(Annonces!$A$2:$A$701,$A23,Annonces!$E$2:$E$701,"En vente",Annonces!$AF$2:$AF$701,"Pro")/COUNTIFS(Annonces!$A$2:$A$701,$A23,Annonces!$E$2:$E$701,"En vente",Annonces!$AF$2:$AF$701,"<>"),"") | AA23: =IFERROR(COUNTIFS(Annonces!$A$2:$A$701,$A23,Annonces!$E$2:$E$701,"En vente",Annonces!$AD$2:$AD$701,"*arnet*")/COUNTIFS(Annonces!$A$2:$A$701,$A23,Annonces!$E$2:$E$701,"En vente",Annonces!$AD$2:$AD$701,"<>"),"") | AB23: =IFERROR(AVERAGEIFS(Annonces!$R$2:$R$701,Annonces!$A$2:$A$701,$A23,Annonces!$E$2:$E$701,"En vente"),"") | AC23: =IFERROR(AVERAGEIFS(Annonces!$J$2:$J$701,Annonces!$A$2:$A$701,$A23,Annonces!$E$2:$E$701,"En vente"),"")
A24: Alfa Romeo 156 2.5 V6 24V | B24: Berline sportive youngtimer | C24: 52.8 | D24: Attendre | E24: 6995 | F24: 4293 | G24: 8050 | H24: =IF(AND(ISNUMBER(E24),ISNUMBER(F24),ISNUMBER(G24),G24>F24),(E24-F24)/(G24-F24),"") | L24: 7010 | M24: 200000 | N24: 8 | O24: 2 | P24: 41 | Q24: 3 | R24: 50 | S24: 65 | T24: 70 | U24: 28 | V24: 50 | W24: 64 | X24: 46310 | Y24: Voir | Z24: =IFERROR(COUNTIFS(Annonces!$A$2:$A$701,$A24,Annonces!$E$2:$E$701,"En vente",Annonces!$AF$2:$AF$701,"Pro")/COUNTIFS(Annonces!$A$2:$A$701,$A24,Annonces!$E$2:$E$701,"En vente",Annonces!$AF$2:$AF$701,"<>"),"") | AA24: =IFERROR(COUNTIFS(Annonces!$A$2:$A$701,$A24,Annonces!$E$2:$E$701,"En vente",Annonces!$AD$2:$AD$701,"*arnet*")/COUNTIFS(Annonces!$A$2:$A$701,$A24,Annonces!$E$2:$E$701,"En vente",Annonces!$AD$2:$AD$701,"<>"),"") | AB24: =IFERROR(AVERAGEIFS(Annonces!$R$2:$R$701,Annonces!$A$2:$A$701,$A24,Annonces!$E$2:$E$701,"En vente"),"") | AC24: =IFERROR(AVERAGEIFS(Annonces!$J$2:$J$701,Annonces!$A$2:$A$701,$A24,Annonces!$E$2:$E$701,"En vente"),"")

Sheet Historique mensuel
A1: Mois | B1: Véhicule | C1: Médiane | D1: Évol. médiane vs mois préc. | E1: P25 | F1: P75 | G1: Cote à km réf. | H1: Évol. cote km réf. | I1: Annonces | J1: Nouvelles annonces | K1: Vendues | L1: Délai de vente | M1: Relevés dans le mois | N1: Score /100 | O1: Évol. score (pts) | P1: Signal
A2: 2026-10 | B2: Alfa Romeo 156 2.5 V6 24V | C2: 6995 | D2: =IF(AND($B2=$B1,ISNUMBER(C2),ISNUMBER(C1)),C2/C1-1,"") | E2: 4293 | F2: 8050 | G2: 7010 | H2: =IF(AND($B2=$B1,ISNUMBER(G2),ISNUMBER(G1)),G2/G1-1,"") | I2: 8 | J2: 10 | K2: 2 | L2: 41 | M2: 2 | N2: 52.8 | O2: =IF(AND($B2=$B1,ISNUMBER(N2),ISNUMBER(N1)),N2-N1,"") | P2: Attendre
A3: 2026-10 | B3: BMW Z3 1.9i / 2.0i | C3: 10245 | D3: =IF(AND($B3=$B2,ISNUMBER(C3),ISNUMBER(C2)),C3/C2-1,"") | E3: 9498 | F3: 11993 | G3: 10900 | H3: =IF(AND($B3=$B2,ISNUMBER(G3),ISNUMBER(G2)),G3/G2-1,"") | I3: 24 | J3: 38 | K3: 0 | M3: 2 | N3: 61.9 | O3: =IF(AND($B3=$B2,ISNUMBER(N3),ISNUMBER(N2)),N3-N2,"") | P3: À surveiller
A4: 2026-09 | B4: Citroën Saxo VTS 16V | C4: 6600 | D4: =IF(AND($B4=$B3,ISNUMBER(C4),ISNUMBER(C3)),C4/C3-1,"") | H4: =IF(AND($B4=$B3,ISNUMBER(G4),ISNUMBER(G3)),G4/G3-1,"") | I4: 2 | J4: 0 | M4: 1 | N4: 43.6 | O4: =IF(AND($B4=$B3,ISNUMBER(N4),ISNUMBER(N3)),N4-N3,"") | P4: Attendre
A5: 2026-10 | B5: Citroën Saxo VTS 16V | C5: 6750 | D5: =IF(AND($B5=$B4,ISNUMBER(C5),ISNUMBER(C4)),C5/C4-1,"") | E5: 5000 | F5: 8850 | G5: 7450 | H5: =IF(AND($B5=$B4,ISNUMBER(G5),ISNUMBER(G4)),G5/G4-1,"") | I5: 40 | J5: 57 | K5: 0 | M5: 2 | N5: 56 | O5: =IF(AND($B5=$B4,ISNUMBER(N5),ISNUMBER(N4)),N5-N4,"") | P5: À surveiller
A6: 2026-10 | B6: Honda S2000 | C6: 23900 | D6: =IF(AND($B6=$B5,ISNUMBER(C6),ISNUMBER(C5)),C6/C5-1,"") | E6: 17950 | F6: 28950 | G6: 22870 | H6: =IF(AND($B6=$B5,ISNUMBER(G6),ISNUMBER(G5)),G6/G5-1,"") | I6: 39 | J6: 51 | K6: 0 | M6: 2 | N6: 65.2 | O6: =IF(AND($B6=$B5,ISNUMBER(N6),ISNUMBER(N5)),N6-N5,"") | P6: À surveiller
A7: 2026-10 | B7: Mazda MX-5 NA | C7: 11990 | D7: =IF(AND($B7=$B6,ISNUMBER(C7),ISNUMBER(C6)),C7/C6-1,"") | E7: 8938 | F7: 13875 | G7: 11470 | H7: =IF(AND($B7=$B6,ISNUMBER(G7),ISNUMBER(G6)),G7/G6-1,"") | I7: 38 | J7: 45 | K7: 0 | M7: 2 | N7: 56.1 | O7: =IF(AND($B7=$B6,ISNUMBER(N7),ISNUMBER(N6)),N7-N6,"") | P7: À surveiller
A8: 2026-10 | B8: Peugeot 205 GTI | C8: 15450 | D8: =IF(AND($B8=$B7,ISNUMBER(C8),ISNUMBER(C7)),C8/C7-1,"") | E8: 13125 | F8: 20000 | G8: 16890 | H8: =IF(AND($B8=$B7,ISNUMBER(G8),ISNUMBER(G7)),G8/G7-1,"") | I8: 40 | J8: 65 | K8: 0 | M8: 2 | N8: 67.3 | O8: =IF(AND($B8=$B7,ISNUMBER(N8),ISNUMBER(N7)),N8-N7,"") | P8: À surveiller
A9: 2026-09 | B9: Peugeot 206 RC | C9: 6790 | D9: =IF(AND($B9=$B8,ISNUMBER(C9),ISNUMBER(C8)),C9/C8-1,"") | H9: =IF(AND($B9=$B8,ISNUMBER(G9),ISNUMBER(G8)),G9/G8-1,"") | I9: 1 | J9: 0 | M9: 1 | N9: 58.2 | O9: =IF(AND($B9=$B8,ISNUMBER(N9),ISNUMBER(N8)),N9-N8,"") | P9: À surveiller
A10: 2026-10 | B10: Peugeot 206 RC | C10: 9000 | D10: =IF(AND($B10=$B9,ISNUMBER(C10),ISNUMBER(C9)),C10/C9-1,"") | E10: 6975 | F10: 12100 | G10: 11050 | H10: =IF(AND($B10=$B9,ISNUMBER(G10),ISNUMBER(G9)),G10/G9-1,"") | I10: 40 | J10: 25 | K10: 0 | M10: 2 | N10: 65.9 | O10: =IF(AND($B10=$B9,ISNUMBER(N10),ISNUMBER(N9)),N10-N9,"") | P10: À surveiller
A11: 2026-09 | B11: Peugeot 208 GTi 30th | C11: 15990 | D11: =IF(AND($B11=$B10,ISNUMBER(C11),ISNUMBER(C10)),C11/C10-1,"") | H11: =IF(AND($B11=$B10,ISNUMBER(G11),ISNUMBER(G10)),G11/G10-1,"") | I11: 7 | J11: 0 | M11: 1 | N11: 67.4 | O11: =IF(AND($B11=$B10,ISNUMBER(N11),ISNUMBER(N10)),N11-N10,"") | P11: À surveiller
A12: 2026-10 | B12: Peugeot 208 GTi 30th | C12: 15900 | D12: =IF(AND($B12=$B11,ISNUMBER(C12),ISNUMBER(C11)),C12/C11-1,"") | E12: 14695 | F12: 17885 | G12: 15360 | H12: =IF(AND($B12=$B11,ISNUMBER(G12),ISNUMBER(G11)),G12/G11-1,"") | I12: 11 | J12: 13 | K12: 2 | L12: 61 | M12: 2 | N12: 70.2 | O12: =IF(AND($B12=$B11,ISNUMBER(N12),ISNUMBER(N11)),N12-N11,"") | P12: Signal d'achat
A13: 2026-10 | B13: Peugeot 306 S16 | C13: 9500 | D13: =IF(AND($B13=$B12,ISNUMBER(C13),ISNUMBER(C12)),C13/C12-1,"") | E13: 8000 | F13: 15000 | G13: 11490 | H13: =IF(AND($B13=$B12,ISNUMBER(G13),ISNUMBER(G12)),G13/G12-1,"") | I13: 33 | J13: 41 | K13: 0 | M13: 2 | N13: 61.9 | O13: =IF(AND($B13=$B12,ISNUMBER(N13),ISNUMBER(N12)),N13-N12,"") | P13: À surveiller
A14: 2026-09 | B14: Porsche 911 997 Carrera S | C14: 51000 | D14: =IF(AND($B14=$B13,ISNUMBER(C14),ISNUMBER(C13)),C14/C13-1,"") | H14: =IF(AND($B14=$B13,ISNUMBER(G14),ISNUMBER(G13)),G14/G13-1,"") | I14: 11 | J14: 0 | M14: 1 | N14: 67.2 | O14: =IF(AND($B14=$B13,ISNUMBER(N14),ISNUMBER(N13)),N14-N13,"") | P14: À surveiller
A15: 2026-10 | B15: Porsche 911 997 Carrera S | C15: 54990 | D15: =IF(AND($B15=$B14,ISNUMBER(C15),ISNUMBER(C14)),C15/C14-1,"") | E15: 49940 | F15: 59900 | G15: 55870 | H15: =IF(AND($B15=$B14,ISNUMBER(G15),ISNUMBER(G14)),G15/G14-1,"") | I15: 39 | J15: 66 | K15: 0 | M15: 2 | N15: 68.9 | O15: =IF(AND($B15=$B14,ISNUMBER(N15),ISNUMBER(N14)),N15-N14,"") | P15: Signal d'achat
A16: 2026-09 | B16: Porsche Boxster 986 | C16: 22425 | D16: =IF(AND($B16=$B15,ISNUMBER(C16),ISNUMBER(C15)),C16/C15-1,"") | H16: =IF(AND($B16=$B15,ISNUMBER(G16),ISNUMBER(G15)),G16/G15-1,"") | I16: 4 | J16: 0 | M16: 1 | N16: 43.1 | O16: =IF(AND($B16=$B15,ISNUMBER(N16),ISNUMBER(N15)),N16-N15,"") | P16: Attendre
A17: 2026-10 | B17: Porsche Boxster 986 | C17: 19890 | D17: =IF(AND($B17=$B16,ISNUMBER(C17),ISNUMBER(C16)),C17/C16-1,"") | E17: 17375 | F17: 21990 | G17: 20520 | H17: =IF(AND($B17=$B16,ISNUMBER(G17),ISNUMBER(G16)),G17/G16-1,"") | I17: 40 | J17: 63 | K17: 0 | M17: 2 | N17: 58.4 | O17: =IF(AND($B17=$B16,ISNUMBER(N17),ISNUMBER(N16)),N17-N16,"") | P17: À surveiller
A18: 2026-09 | B18: Porsche Boxster 987 | C18: 43990 | D18: =IF(AND($B18=$B17,ISNUMBER(C18),ISNUMBER(C17)),C18/C17-1,"") | H18: =IF(AND($B18=$B17,ISNUMBER(G18),ISNUMBER(G17)),G18/G17-1,"") | I18: 5 | J18: 0 | M18: 1 | N18: 38.3 | O18: =IF(AND($B18=$B17,ISNUMBER(N18),ISNUMBER(N17)),N18-N17,"") | P18: Attendre
A19: 2026-10 | B19: Porsche Boxster 987 | C19: 29250 | D19: =IF(AND($B19=$B18,ISNUMBER(C19),ISNUMBER(C18)),C19/C18-1,"") | E19: 26675 | F19: 34493 | G19: 32020 | H19: =IF(AND($B19=$B18,ISNUMBER(G19),ISNUMBER(G18)),G19/G18-1,"") | I19: 40 | J19: 62 | K19: 0 | M19: 2 | N19: 60.1 | O19: =IF(AND($B19=$B18,ISNUMBER(N19),ISNUMBER(N18)),N19-N18,"") | P19: À surveiller
A20: 2026-09 | B20: Renault Clio II RS (172/182 ch) | C20: 8899.5 | D20: =IF(AND($B20=$B19,ISNUMBER(C20),ISNUMBER(C19)),C20/C19-1,"") | H20: =IF(AND($B20=$B19,ISNUMBER(G20),ISNUMBER(G19)),G20/G19-1,"") | I20: 2 | J20: 0 | M20: 1 | N20: 52 | O20: =IF(AND($B20=$B19,ISNUMBER(N20),ISNUMBER(N19)),N20-N19,"") | P20: Attendre
A21: 2026-10 | B21: Renault Clio II RS (172/182 ch) | C21: 10195 | D21: =IF(AND($B21=$B20,ISNUMBER(C21),ISNUMBER(C20)),C21/C20-1,"") | E21: 7900 | F21: 12248 | G21: 10520 | H21: =IF(AND($B21=$B20,ISNUMBER(G21),ISNUMBER(G20)),G21/G20-1,"") | I21: 36 | J21: 53 | K21: 0 | M21: 2 | N21: 62.8 | O21: =IF(AND($B21=$B20,ISNUMBER(N21),ISNUMBER(N20)),N21-N20,"") | P21: À surveiller
A22: 2026-10 | B22: Renault Mégane II RS R26 | C22: 22990 | D22: =IF(AND($B22=$B21,ISNUMBER(C22),ISNUMBER(C21)),C22/C21-1,"") | E22: 19900 | F22: 24495 | G22: 23170 | H22: =IF(AND($B22=$B21,ISNUMBER(G22),ISNUMBER(G21)),G22/G21-1,"") | I22: 15 | J22: 20 | K22: 5 | L22: 62 | M22: 2 | N22: 58 | O22: =IF(AND($B22=$B21,ISNUMBER(N22),ISNUMBER(N21)),N22-N21,"") | P22: À surveiller
A23: 2026-09 | B23: Renault Twingo 1 découvrable | C23: 5490 | D23: =IF(AND($B23=$B22,ISNUMBER(C23),ISNUMBER(C22)),C23/C22-1,"") | H23: =IF(AND($B23=$B22,ISNUMBER(G23),ISNUMBER(G22)),G23/G22-1,"") | I23: 6 | J23: 0 | M23: 1 | N23: 46.5 | O23: =IF(AND($B23=$B22,ISNUMBER(N23),ISNUMBER(N22)),N23-N22,"") | P23: Attendre
A24: 2026-10 | B24: Renault Twingo 1 découvrable | C24: 3000 | D24: =IF(AND($B24=$B23,ISNUMBER(C24),ISNUMBER(C23)),C24/C23-1,"") | E24: 2400 | F24: 3650 | G24: 3530 | H24: =IF(AND($B24=$B23,ISNUMBER(G24),ISNUMBER(G23)),G24/G23-1,"") | I24: 37 | J24: 50 | K24: 0 | M24: 2 | N24: 65.5 | O24: =IF(AND($B24=$B23,ISNUMBER(N24),ISNUMBER(N23)),N24-N23,"") | P24: À surveiller
A25: 2026-10 | B25: Volkswagen Golf IV GTI 25th Anniversary | C25: 11000 | D25: =IF(AND($B25=$B24,ISNUMBER(C25),ISNUMBER(C24)),C25/C24-1,"") | E25: 11000 | F25: 11000 | G25: 11000 | H25: =IF(AND($B25=$B24,ISNUMBER(G25),ISNUMBER(G24)),G25/G24-1,"") | I25: 1 | J25: 1 | K25: 0 | M25: 1 | N25: 61 | O25: =IF(AND($B25=$B24,ISNUMBER(N25),ISNUMBER(N24)),N25-N24,"") | P25: À surveiller

Sheet Médianes par mois
A1: Véhicule | B1: 2026-09 | C1: 2026-10
A2: Alfa Romeo 156 2.5 V6 24V | B2: =IFERROR(AVERAGEIFS('Historique mensuel'!$C$2:$C$25,'Historique mensuel'!$B$2:$B$25,$A2,'Historique mensuel'!$A$2:$A$25,B$1),"") | C2: =IFERROR(AVERAGEIFS('Historique mensuel'!$C$2:$C$25,'Historique mensuel'!$B$2:$B$25,$A2,'Historique mensuel'!$A$2:$A$25,C$1),"")
A3: BMW Z3 1.9i / 2.0i | B3: =IFERROR(AVERAGEIFS('Historique mensuel'!$C$2:$C$25,'Historique mensuel'!$B$2:$B$25,$A3,'Historique mensuel'!$A$2:$A$25,B$1),"") | C3: =IFERROR(AVERAGEIFS('Historique mensuel'!$C$2:$C$25,'Historique mensuel'!$B$2:$B$25,$A3,'Historique mensuel'!$A$2:$A$25,C$1),"")
A4: Citroën Saxo VTS 16V | B4: =IFERROR(AVERAGEIFS('Historique mensuel'!$C$2:$C$25,'Historique mensuel'!$B$2:$B$25,$A4,'Historique mensuel'!$A$2:$A$25,B$1),"") | C4: =IFERROR(AVERAGEIFS('Historique mensuel'!$C$2:$C$25,'Historique mensuel'!$B$2:$B$25,$A4,'Historique mensuel'!$A$2:$A$25,C$1),"")
A5: Honda S2000 | B5: =IFERROR(AVERAGEIFS('Historique mensuel'!$C$2:$C$25,'Historique mensuel'!$B$2:$B$25,$A5,'Historique mensuel'!$A$2:$A$25,B$1),"") | C5: =IFERROR(AVERAGEIFS('Historique mensuel'!$C$2:$C$25,'Historique mensuel'!$B$2:$B$25,$A5,'Historique mensuel'!$A$2:$A$25,C$1),"")
A6: Mazda MX-5 NA | B6: =IFERROR(AVERAGEIFS('Historique mensuel'!$C$2:$C$25,'Historique mensuel'!$B$2:$B$25,$A6,'Historique mensuel'!$A$2:$A$25,B$1),"") | C6: =IFERROR(AVERAGEIFS('Historique mensuel'!$C$2:$C$25,'Historique mensuel'!$B$2:$B$25,$A6,'Historique mensuel'!$A$2:$A$25,C$1),"")
A7: Peugeot 205 GTI | B7: =IFERROR(AVERAGEIFS('Historique mensuel'!$C$2:$C$25,'Historique mensuel'!$B$2:$B$25,$A7,'Historique mensuel'!$A$2:$A$25,B$1),"") | C7: =IFERROR(AVERAGEIFS('Historique mensuel'!$C$2:$C$25,'Historique mensuel'!$B$2:$B$25,$A7,'Historique mensuel'!$A$2:$A$25,C$1),"")
A8: Peugeot 206 RC | B8: =IFERROR(AVERAGEIFS('Historique mensuel'!$C$2:$C$25,'Historique mensuel'!$B$2:$B$25,$A8,'Historique mensuel'!$A$2:$A$25,B$1),"") | C8: =IFERROR(AVERAGEIFS('Historique mensuel'!$C$2:$C$25,'Historique mensuel'!$B$2:$B$25,$A8,'Historique mensuel'!$A$2:$A$25,C$1),"")
A9: Peugeot 208 GTi 30th | B9: =IFERROR(AVERAGEIFS('Historique mensuel'!$C$2:$C$25,'Historique mensuel'!$B$2:$B$25,$A9,'Historique mensuel'!$A$2:$A$25,B$1),"") | C9: =IFERROR(AVERAGEIFS('Historique mensuel'!$C$2:$C$25,'Historique mensuel'!$B$2:$B$25,$A9,'Historique mensuel'!$A$2:$A$25,C$1),"")
A10: Peugeot 306 S16 | B10: =IFERROR(AVERAGEIFS('Historique mensuel'!$C$2:$C$25,'Historique mensuel'!$B$2:$B$25,$A10,'Historique mensuel'!$A$2:$A$25,B$1),"") | C10: =IFERROR(AVERAGEIFS('Historique mensuel'!$C$2:$C$25,'Historique mensuel'!$B$2:$B$25,$A10,'Historique mensuel'!$A$2:$A$25,C$1),"")
A11: Porsche 911 997 Carrera S | B11: =IFERROR(AVERAGEIFS('Historique mensuel'!$C$2:$C$25,'Historique mensuel'!$B$2:$B$25,$A11,'Historique mensuel'!$A$2:$A$25,B$1),"") | C11: =IFERROR(AVERAGEIFS('Historique mensuel'!$C$2:$C$25,'Historique mensuel'!$B$2:$B$25,$A11,'Historique mensuel'!$A$2:$A$25,C$1),"")
A12: Porsche Boxster 986 | B12: =IFERROR(AVERAGEIFS('Historique mensuel'!$C$2:$C$25,'Historique mensuel'!$B$2:$B$25,$A12,'Historique mensuel'!$A$2:$A$25,B$1),"") | C12: =IFERROR(AVERAGEIFS('Historique mensuel'!$C$2:$C$25,'Historique mensuel'!$B$2:$B$25,$A12,'Historique mensuel'!$A$2:$A$25,C$1),"")
A13: Porsche Boxster 987 | B13: =IFERROR(AVERAGEIFS('Historique mensuel'!$C$2:$C$25,'Historique mensuel'!$B$2:$B$25,$A13,'Historique mensuel'!$A$2:$A$25,B$1),"") | C13: =IFERROR(AVERAGEIFS('Historique mensuel'!$C$2:$C$25,'Historique mensuel'!$B$2:$B$25,$A13,'Historique mensuel'!$A$2:$A$25,C$1),"")
... A17: Volkswagen Golf IV GTI 25th Anniversary | B17: =IFERROR(AVERAGEIFS('Historique mensuel'!$C$2:$C$25,'Historique mensuel'!$B$2:$B$25,$A17,'Historique mensuel'!$A$2:$A$25,B$1),"") | C17: =IFERROR(AVERAGEIFS('Historique mensuel'!$C$2:$C$25,'Historique mensuel'!$B$2:$B$25,$A17,'Historique mensuel'!$A$2:$A$25,C$1),"")

Sheet Indice base 100
A1: Évolution de la médiane, base 100 au premier mois suivi de chaque véhicule
A2: Valeurs calculées par le robot à partir de l'onglet Historique mensuel (cases vides = pas de relevé ce mois-là, pour que le graphique ne les compte pas comme des zéros).
A4: Mois | B4: Alfa Romeo 156 2.5 V6 24V | C4: BMW Z3 1.9i / 2.0i | D4: Citroën Saxo VTS 16V | E4: Honda S2000 | F4: Mazda MX-5 NA | G4: Peugeot 205 GTI | H4: Peugeot 206 RC | I4: Peugeot 208 GTi 30th | J4: Peugeot 306 S16 | K4: Porsche 911 997 Carrera S | L4: Porsche Boxster 986 | M4: Porsche Boxster 987 | N4: Renault Clio II RS (172/182 ch) | O4: Renault Mégane II RS R26 | P4: Renault Twingo 1 découvrable | Q4: Volkswagen Golf IV GTI 25th Anniversary
A5: 2026-09 | D5: 100 | H5: 100 | I5: 100 | K5: 100 | L5: 100 | M5: 100 | N5: 100 | P5: 100
A6: 2026-10 | B6: 100 | C6: 100 | D6: 102.3 | E6: 100 | F6: 100 | G6: 100 | H6: 132.5 | I6: 99.4 | J6: 100 | K6: 107.8 | L6: 88.7 | M6: 66.5 | N6: 114.6 | O6: 100 | P6: 54.6 | Q6: 100

Sheet Relevés
A1: Date | B1: Véhicule | C1: Source | D1: Annonces | E1: Min | F1: P25 | G1: Médiane | H1: P75 | I1: Max | J1: Km médian | K1: Cote à km réf. | L1: Km réf. | M1: Nouvelles | N1: Vendues | O1: Délai de vente | P1: Part de pros | Q1: Annonces écartées
A2: 46310 | B2: Alfa Romeo 156 2.5 V6 24V | C2: apify | D2: 8 | E2: 3200 | F2: 4293 | G2: 6995 | H2: 8050 | I2: 14900 | J2: 201000 | K2: 7010 | L2: 200000 | M2: 2 | N2: 2 | O2: 41 | P2: 0.25 | Q2: 6
A3: 46310 | B3: BMW Z3 1.9i / 2.0i | C3: apify | D3: 24 | E3: 7000 | F3: 9498 | G3: 10245 | H3: 11993 | I3: 15000 | J3: 142000 | K3: 10900 | L3: 130000 | M3: 24 | N3: 0 | P3: 0.58 | Q3: 16
A4: 46310 | B4: Citroën Saxo VTS 16V | C4: apify | D4: 40 | E4: 800 | F4: 5000 | G4: 6750 | H4: 8850 | I4: 16000 | J4: 188000 | K4: 7450 | L4: 150000 | M4: 17 | N4: 0 | P4: 0.03 | Q4: 0
A5: 46310 | B5: Honda S2000 | C5: apify | D5: 39 | E5: 4599 | F5: 17950 | G5: 23900 | H5: 28950 | I5: 49990 | J5: 135000 | K5: 22870 | L5: 140000 | M5: 12 | N5: 0 | P5: 0.38 | Q5: 1
A6: 46310 | B6: Mazda MX-5 NA | C6: apify | D6: 38 | E6: 3000 | F6: 8938 | G6: 11990 | H6: 13875 | I6: 17990 | J6: 163000 | K6: 11470 | L6: 160000 | M6: 8 | N6: 0 | P6: 0.16 | Q6: 2
A7: 46310 | B7: Peugeot 205 GTI | C7: apify | D7: 40 | E7: 9800 | F7: 13125 | G7: 15450 | H7: 20000 | I7: 31000 | J7: 187000 | K7: 16890 | L7: 190000 | M7: 27 | N7: 0 | P7: 0.13 | Q7: 0
A8: 46310 | B8: Peugeot 206 RC | C8: apify | D8: 40 | E8: 5900 | F8: 6975 | G8: 9000 | H8: 12100 | I8: 17900 | J8: 170000 | K8: 11050 | L8: 150000 | M8: 23 | N8: 0 | P8: 0.08 | Q8: 0
A9: 46310 | B9: Peugeot 208 GTi 30th | C9: apify | D9: 11 | E9: 10500 | F9: 14695 | G9: 15900 | H9: 17885 | I9: 23490 | J9: 84000 | K9: 15360 | L9: 100000 | M9: 3 | N9: 2 | O9: 61 | P9: 0.45 | Q9: 1
A10: 46310 | B10: Peugeot 306 S16 | C10: apify | D10: 33 | E10: 3500 | F10: 8000 | G10: 9500 | H10: 15000 | I10: 26800 | J10: 191000 | K10: 11490 | L10: 180000 | M10: 16 | N10: 0 | P10: 0.03 | Q10: 7
A11: 46310 | B11: Porsche 911 997 Carrera S | C11: apify | D11: 39 | E11: 45990 | F11: 49940 | G11: 54990 | H11: 59900 | I11: 69990 | J11: 105000 | K11: 55870 | L11: 100000 | M11: 30 | N11: 0 | P11: 0.85 | Q11: 1
A12: 46310 | B12: Porsche Boxster 986 | C12: apify | D12: 40 | E12: 10999 | F12: 17375 | G12: 19890 | H12: 21990 | I12: 26000 | J12: 125000 | K12: 20520 | L12: 110000 | M12: 23 | N12: 0 | P12: 0.5 | Q12: 0
A13: 46310 | B13: Porsche Boxster 987 | C13: apify | D13: 40 | E13: 19900 | F13: 26675 | G13: 29250 | H13: 34493 | I13: 49900 | J13: 99000 | K13: 32020 | L13: 80000 | M13: 24 | N13: 0 | P13: 0.55 | Q13: 0
A14: 46310 | B14: Renault Clio II RS (172/182 ch) | C14: apify | D14: 36 | E14: 4000 | F14: 7900 | G14: 10195 | H14: 12248 | I14: 19500 | J14: 167000 | K14: 10520 | L14: 160000 | M14: 15 | N14: 0 | P14: 0.25 | Q14: 4
A15: 46310 | B15: Renault Mégane II RS R26 | C15: apify | D15: 15 | E15: 14900 | F15: 19900 | G15: 22990 | H15: 24495 | I15: 31490 | J15: 109000 | K15: 23170 | L15: 100000 | M15: 2 | N15: 5 | O15: 62 | P15: 0.6 | Q15: 3
A16: 46310 | B16: Renault Twingo 1 découvrable | C16: apify | D16: 37 | E16: 1690 | F16: 2400 | G16: 3000 | H16: 3650 | I16: 5990 | J16: 175000 | K16: 3530 | L16: 150000 | M16: 23 | N16: 0 | P16: 0.16 | Q16: 3
A17: 46310 | B17: Volkswagen Golf IV GTI 25th Anniversary | C17: apify | D17: 1 | E17: 11000 | F17: 11000 | G17: 11000 | H17: 11000 | I17: 11000 | J17: 195000 | K17: 11000 | L17: 200000 | M17: 1 | N17: 0 | P17: 0 | Q17: 4
A18: 46296 | B18: Alfa Romeo 156 2.5 V6 24V | C18: apify | D18: 8 | E18: 3200 | F18: 4293 | G18: 5695 | H18: 7125 | I18: 8800 | J18: 198000 | K18: 5700 | L18: 200000 | M18: 8 | N18: 0 | P18: 0.25 | Q18: 6
A19: 46296 | B19: BMW Z3 1.9i / 2.0i | C19: apify | D19: 14 | E19: 7490 | F19: 9990 | G19: 11240 | H19: 12740 | I19: 17900 | J19: 125000 | K19: 12020 | L19: 130000 | M19: 14 | N19: 0 | P19: 0.86 | Q19: 26
A20: 46296 | B20: Citroën Saxo VTS 16V | C20: apify | D20: 40 | E20: 1600 | F20: 4875 | G20: 6350 | H20: 8350 | I20: 12980 | J20: 189000 | K20: 7750 | L20: 150000 | M20: 40 | N20: 0 | P20: 0.03 | Q20: 0
A21: 46296 | B21: Honda S2000 | C21: apify | D21: 39 | E21: 4599 | F21: 14900 | G21: 21000 | H21: 27500 | I21: 49990 | J21: 139000 | K21: 22260 | L21: 140000 | M21: 39 | N21: 0 | P21: 0.38 | Q21: 1
A22: 46296 | B22: Mazda MX-5 NA | C22: apify | D22: 37 | E22: 3990 | F22: 9500 | G22: 11980 | H22: 13500 | I22: 17990 | J22: 163000 | K22: 11580 | L22: 160000 | M22: 37 | N22: 0 | P22: 0.14 | Q22: 3
A23: 46296 | B23: Peugeot 205 GTI | C23: apify | D23: 38 | E23: 5500 | F23: 14925 | G23: 18000 | H23: 20675 | I23: 31000 | J23: 185000 | K23: 17870 | L23: 190000 | M23: 38 | N23: 0 | P23: 0.11 | Q23: 2
A24: 46296 | B24: Peugeot 206 RC | C24: apify | D24: 39 | E24: 5400 | F24: 7500 | G24: 9990 | H24: 12600 | I24: 18500 | J24: 159000 | K24: 11240 | L24: 150000 | M24: 2 | N24: 0 | P24: 0.1 | Q24: 1
A25: 46296 | B25: Peugeot 208 GTi 30th | C25: apify | D25: 10 | E25: 10500 | F25: 13368 | G25: 14940 | H25: 17100 | I25: 23490 | J25: 110000 | K25: 16280 | L25: 100000 | M25: 10 | N25: 0 | P25: 0.4 | Q25: 0
A26: 46296 | B26: Peugeot 306 S16 | C26: apify | D26: 25 | E26: 1000 | F26: 6800 | G26: 8200 | H26: 12800 | I26: 26800 | J26: 185000 | K26: 9790 | L26: 180000 | M26: 25 | N26: 0 | P26: 0 | Q26: 5
A27: 46296 | B27: Porsche 911 997 Carrera S | C27: apify | D27: 36 | E27: 39990 | F27: 49988 | G27: 51395 | H27: 56240 | I27: 69599 | J27: 110000 | K27: 55200 | L27: 100000 | M27: 36 | N27: 0 | P27: 0.83 | Q27: 4
... A32: 46296 | B32: Renault Twingo 1 découvrable | C32: apify | D32: 27 | E32: 699 | F32: 2095 | G32: 2990 | H32: 3550 | I32: 5990 | J32: 165000 | K32: 3380 | L32: 150000 | M32: 27 | N32: 0 | P32: 0.22 | Q32: 13
A33: 46273 | B33: Citroën Saxo VTS 16V | C33: manuel | D33: 2 | E33: 6500 | G33: 6600 | I33: 6700 | J33: 153683
A34: 46273 | B34: Peugeot 206 RC | C34: manuel | D34: 1 | E34: 6790 | G34: 6790 | I34: 6790 | J34: 244000
A35: 46273 | B35: Peugeot 208 GTi 30th | C35: manuel | D35: 7 | E35: 12990 | G35: 15990 | I35: 23490 | J35: 108000
A36: 46273 | B36: Porsche 911 997 Carrera S | C36: manuel | D36: 11 | E36: 46500 | G36: 51000 | I36: 74900 | J36: 100000
A37: 46273 | B37: Porsche Boxster 986 | C37: manuel | D37: 4 | E37: 17986 | G37: 22425 | I37: 26900 | J37: 110000
A38: 46273 | B38: Porsche Boxster 987 | C38: manuel | D38: 5 | E38: 33000 | G38: 43990 | I38: 72986 | J38: 65000
A39: 46273 | B39: Renault Clio II RS (172/182 ch) | C39: manuel | D39: 2 | E39: 6000 | G39: 8899.5 | I39: 11799 | J39: 168000
A40: 46273 | B40: Renault Twingo 1 découvrable | C40: manuel | D40: 6 | E40: 1500 | G40: 5490 | I40: 6290 | J40: 150000

Sheet Annonces
A1: Véhicule | B1: Titre | C1: Version | D1: Finition | E1: Statut | F1: Publiée le | G1: Première vue | H1: Dernière vue | I1: Partie le | J1: Jours en ligne | K1: Prix initial | L1: Prix actuel | M1: Baisse de prix | N1: Nb de baisses | O1: Ancien prix affiché | P1: Estimation LBC min | Q1: Estimation LBC max | R1: Écart vs estimation LBC | S1: Positionnement LBC | T1: Km | U1: Année | V1: Mise en circulation | W1: Carburant | X1: Boîte | Y1: Puissance DIN (ch) | Z1: Puissance fiscale (CV) | AA1: Couleur | AB1: Portes | AC1: Type | AD1: Entretien | AE1: Historique | AF1: Vendeur | AG1: Ville | AH1: Code postal | AI1: Département | AJ1: Région | AK1: Photos | AL1: Remontée payante | AM1: Urgent | AN1: Description (extrait) | AO1: Autres caractéristiques | AP1: Annonce | AQ1: Id
A2: Alfa Romeo 156 2.5 V6 24V | B2: Alfa Roméo 156 SW V6 2,5l 24s | E2: En vente | F2: 46303 | G2: 46237 | H2: 46310 | J2: =IF(OR(ISNUMBER(F2),ISNUMBER(G2)),IF(ISNUMBER(I2),I2,H2)-IF(ISNUMBER(F2),F2,G2),"") | K2: 7500 | L2: 7500 | M2: =IF(AND(ISNUMBER(K2),ISNUMBER(L2),K2>0),1-L2/K2,"") | N2: 0 | R2: =IF(AND(ISNUMBER(L2),ISNUMBER(P2),ISNUMBER(Q2)),L2/((P2+Q2)/2)-1,"") | T2: 316324 | U2: 2003 | V2: 10/2003 | W2: Essence | X2: Manuelle | Y2: 190 | Z2: 14 | AA2: Noir | AB2: 5 | AC2: Break | AF2: Particulier | AG2: La Chaussée-Saint-Victor | AH2: 41260 | AI2: Loir-et-Cher | AJ2: Centre | AK2: 3 | AM2: Non | AN2: Alfa Roméo 156 de 2003 V6 Busso 2,5l 24 soupapes finition TI. Parfaitement entretenue : courroie de distribution et pompe à eau faites en 2024 (facture). vidange moteur boîte 2025 (facture) Intérieur cuir noir spécifique TI en excellent état général. 4 Pneus neuf Triangle train avant récent. Alternateur, démarreur, embrayage remplacer Voiture avec entretien suivi depuis l'achat | AO2: Dommages : Non endommagé ; Sellerie : Tout cuir ; Équipements intérieurs : Jantes en alliage, Régulateur de vitesse ; vehicle_euro_emissions_standard : Euro 3 ; Permis : Avec permis ; Importé : false | AP2: Voir | AQ2: 2903975057
A3: Alfa Romeo 156 2.5 V6 24V | B3: Alfa Romeo 156 2.5 V6 Busso | E3: En vente | F3: 46259 | G3: 46259 | H3: 46310 | J3: =IF(OR(ISNUMBER(F3),ISNUMBER(G3)),IF(ISNUMBER(I3),I3,H3)-IF(ISNUMBER(F3),F3,G3),"") | K3: 8800 | L3: 8800 | M3: =IF(AND(ISNUMBER(K3),ISNUMBER(L3),K3>0),1-L3/K3,"") | N3: 0 | R3: =IF(AND(ISNUMBER(L3),ISNUMBER(P3),ISNUMBER(Q3)),L3/((P3+Q3)/2)-1,"") | T3: 200000 | U3: 2001 | V3: 06/2001 | W3: Essence | X3: Manuelle | Y3: 192 | Z3: 13 | AA3: Gris | AB3: 4 | AC3: Berline | AD3: Véhicule non fumeur, Factures disponibles, Réparations utiles déjà faites | AF3: Particulier | AG3: Waldighofen | AH3: 68640 | AI3: Haut-Rhin | AJ3: Alsace | AK3: 10 | AM3: Non | AN3: Magnifique Alfa Romeo 156 équipée du légendaire V6 Busso 2.5 24V atmosphérique (192 ch), un moteur recherché pour sa sonorité exceptionnelle et son caractère unique. 200 000 km – boîte manuelle – très bel état général. Véhicule importé de Suisse, avec historique et factures d’entretien disponibles. Nombreux travaux récents réalisés : * Ligne d’échappement Ragazzon * Ressorts Eibach neufs * Train avant révisé (rotules, articulations…) * Pompe à essence neuve * Joints de couvre-culasse remplacés * | AO3: vehicle_technical_inspection_valid : Oui ; Contrôle technique : 2028 ; Sellerie : Tout cuir ; Équipements intérieurs : Climatisation ; Permis : Avec permis ; Importé : false | AP3: Voir | AQ3: 3222893175
A4: Alfa Romeo 156 2.5 V6 24V | B4: Alfa romeo 156 2.5 v6 24v | C4: 156 2.5 V6 24v | D4: Base | E4: En vente | F4: 46225 | G4: 46225 | H4: 46310 | J4: =IF(OR(ISNUMBER(F4),ISNUMBER(G4)),IF(ISNUMBER(I4),I4,H4)-IF(ISNUMBER(F4),F4,G4),"") | K4: 6490 | L4: 6490 | M4: =IF(AND(ISNUMBER(K4),ISNUMBER(L4),K4>0),1-L4/K4,"") | N4: 0 | O4: 6790 | R4: =IF(AND(ISNUMBER(L4),ISNUMBER(P4),ISNUMBER(Q4)),L4/((P4+Q4)/2)-1,"") | T4: 196500 | U4: 1998 | V4: 04/1998 | W4: Essence | X4: Manuelle | Y4: 190 | Z4: 14 | AA4: Bleu | AB4: 4 | AC4: Berline | AF4: Pro | AG4: Abbeville | AH4: 80100 | AI4: Somme | AJ4: Picardie | AK4: 43 | AM4: Non | AN4: L'Agence TransakAuto ABBEVILLE, société spécialisée en courtage automobile, 1er réseau d'intermédiation automobile auprès des particuliers avec + de 180 agences en France depuis 2011, vous propose ce véhicule Alfa Romeo, 156, Bleu, 14 chevaux fiscaux, 4 portes, 196 500 km. ⚠ 🔦 Véhicule visible uniquement sur rdv à l'agence TransakAuto ABBEVILLE, du mardi au samedi de Lundi - Vendredi 10h - 19h Samedi 10h - 18h Véhicule en dépôt-vente [non stocké sur place]. Visible uniquement sur rendez-vous da | AO4: Équipements intérieurs : Climatisation, Jantes en alliage ; VO récent : false ; custom_ref : VO42668613 ; Importé : true ; vehicle_history_report_status : visible ; spare_parts_availability : Non renseignée | AP4: Voir | AQ4: 3237198858
A5: Alfa Romeo 156 2.5 V6 24V | B5: Alfa 156 2.5 v6 GPL | E5: En vente | F5: 46267 | G5: 46267 | H5: 46310 | J5: =IF(OR(ISNUMBER(F5),ISNUMBER(G5)),IF(ISNUMBER(I5),I5,H5)-IF(ISNUMBER(F5),F5,G5),"") | K5: 3200 | L5: 3200 | M5: =IF(AND(ISNUMBER(K5),ISNUMBER(L5),K5>0),1-L5/K5,"") | N5: 0 | R5: =IF(AND(ISNUMBER(L5),ISNUMBER(P5),ISNUMBER(Q5)),L5/((P5+Q5)/2)-1,"") | T5: 202000 | U5: 1999 | V5: 07/1999 | W5: Essence | X5: Manuelle | Y5: 190 | Z5: 13 | AA5: Noir | AB5: 4 | AC5: Berline | AF5: Particulier | AG5: Romans | AH5: 79260 | AI5: Deux-Sèvres | AJ5: Poitou-Charentes | AK5: 3 | AM5: Non | AN5: Alfa 156 2.5 v6 équipe GPL 202000 km Sortie de grange n' a pas roulé depuis 6 ans . Démarré de temps en temps pour la lubrification. Amortisseur bilstein Ressort court H&R Intermédiaire ragazzon Silencieux ragazzon Intérieur cuir momo | AO5: Permis : Avec permis ; Importé : false | AP5: Voir | AQ5: 3261414202
A6: Alfa Romeo 156 2.5 V6 24V | B6: Alfa romeo 166 v6 busso 2003 | E6: En vente | F6: 46268 | G6: 46268 | H6: 46310 | J6: =IF(OR(ISNUMBER(F6),ISNUMBER(G6)),IF(ISNUMBER(I6),I6,H6)-IF(ISNUMBER(F6),F6,G6),"") | K6: 4390 | L6: 4390 | M6: =IF(AND(ISNUMBER(K6),ISNUMBER(L6),K6>0),1-L6/K6,"") | N6: 0 | R6: =IF(AND(ISNUMBER(L6),ISNUMBER(P6),ISNUMBER(Q6)),L6/((P6+Q6)/2)-1,"") | T6: 207800 | U6: 2003 | V6: 01/2003 | W6: Essence | X6: Manuelle | Y6: 188 | Z6: 14 | AA6: Gris | AB6: 4 | AC6: Berline | AD6: Carnet d'entretien disponible, Véhicule non fumeur, Factures disponibles | AF6: Particulier | AG6: Lapalisse | AH6: 03120 | AI6: Allier | AJ6: Auvergne | AK6: 3 | AM6: Non | AN6: Vends mon Alfa Romeo 166 V6 de 2003 avec 207800kms moteur busso 2.5 V6 188 ch (156 / 164) beaucoup d'options intérieur cuir, gps, radio cd, régulateur de vitesse, climatisation, jantes alu etc Le véhicule est en bon état pour son âge pochette de bord disponible (factures aussi) Moteur boite fonctionne parfaitement (distribution 2018) CT ok et papiers à mon nom Plus d'information par Téléphone uniquement ,merci échange possible 4x4 ou véhicule sportive gti 16 crx vtec turbo.. Prix à déb si achete | AO6: Dommages : Bon état général ; Sellerie : Tout cuir ; Équipements intérieurs : Climatisation, Coffre à ouverture électrique, Jantes en alliage, Ordinateur de bord, Phares anti-brouillard, Roue de secours, Régulateur de vitesse, Sièges chauffants, Sièges en cuir, Sièges électriques, Système de navigation ; Permis : Avec permis ; Importé : false | AP6: Voir | AQ6: 3262191550
A7: Alfa Romeo 156 2.5 V6 24V | B7: Alfa Romeo 156 v6 SW 2.5 | E7: En vente | F7: 46289 | G7: 46289 | H7: 46310 | J7: =IF(OR(ISNUMBER(F7),ISNUMBER(G7)),IF(ISNUMBER(I7),I7,H7)-IF(ISNUMBER(F7),F7,G7),"") | K7: 4000 | L7: 4000 | M7: =IF(AND(ISNUMBER(K7),ISNUMBER(L7),K7>0),1-L7/K7,"") | N7: 0 | R7: =IF(AND(ISNUMBER(L7),ISNUMBER(P7),ISNUMBER(Q7)),L7/((P7+Q7)/2)-1,"") | T7: 175000 | U7: 2004 | V7: 01/2004 | W7: Essence | X7: Manuelle | Y7: 192 | Z7: 14 | AA7: Noir | AB7: 5 | AC7: Berline | AD7: Factures disponibles, Carnet d'entretien disponible | AF7: Particulier | AG7: Mortcerf | AH7: 77163 | AI7: Seine-et-Marne | AJ7: Ile-de-France | AK7: 3 | AM7: Non | AN7: Bonjour Je vends mon Alfa Romeo 156 v6 2.5 En break, SW. Phase 3. Assez bon état général. 178 000 kms Cuir beige abricot a l intérieur Entretien effectué, distribution, embrayage, bougies, soufflet de transmission, pompe a eau.... Ct ok Parcours toutes distances. Disponible pour tous renseignements | AO7: vehicle_technical_inspection_valid : Non ; Dommages : Bon état général ; Sellerie : Tout cuir ; Équipements intérieurs : Climatisation, Jantes en alliage, Ordinateur de bord, Régulateur de vitesse, Rétroviseurs dégivrants, Siège arrière rabattable, Siège réglable en hauteur, Sièges en cuir, Vitres électriques arrières, Volant réglable en hauteur, Volant réglable en profondeur ; vehicle_euro_emissions_standard : Euro 5 ; Permis : Avec permis ; Importé : false ; vehicle_history_teaser_critair : 3 ; vehicle_history_teaser_owners : 5 ; vehicle_history_teaser_expertises : false ; vehicle_history_teaser_special_uses : false ; vehicle_history_teaser_atypical_operations : false ; vehicle_history_teaser_importations : false | AP7: Voir | AQ7: 3275564839
A8: Alfa Romeo 156 2.5 V6 24V | B8: Alfa Romeo 156 2.5 V6 Busso Rouge 1997 | E8: En vente | F8: 46298 | G8: 46298 | H8: 46310 | J8: =IF(OR(ISNUMBER(F8),ISNUMBER(G8)),IF(ISNUMBER(I8),I8,H8)-IF(ISNUMBER(F8),F8,G8),"") | K8: 14900 | L8: 14900 | M8: =IF(AND(ISNUMBER(K8),ISNUMBER(L8),K8>0),1-L8/K8,"") | N8: 0 | R8: =IF(AND(ISNUMBER(L8),ISNUMBER(P8),ISNUMBER(Q8)),L8/((P8+Q8)/2)-1,"") | T8: 55000 | U8: 1997 | V8: 11/1997 | W8: Essence | X8: Manuelle | Y8: 190 | Z8: 14 | AA8: Rouge | AB8: 4 | AC8: Berline | AF8: Pro | AG8: Saint-Junien | AH8: 87200 | AI8: Haute-Vienne | AJ8: Limousin | AK8: 5 | AM8: Non | AN8: La Maison du Cylindre, garage spécialisé dans l'achat-vente et l'entretien de véhicules de collection, situé en Haute-Vienne (87), vous propose : Alfa Romeo 156 2.5 V6 Busso Rouge 1997 en superbe état intérieur et extérieur Kilométrage : 55 000 km relevé compteur Moteur : V6 Busso 2.5L 190ch Boîte de vitesses manuelle 6 rapports Teinte Rosso Alfa Sellerie velours gris logotée Alfa Romeo Freins à disques ventilés à l'avant ABS Direction assistée Vitres électriques Fermeture centralisée Rétroviseu | AO8: Sellerie : Tissu ; Permis : Sans permis ; VO récent : false ; Importé : false ; vehicle_history_report_status : visible ; vehicle_history_teaser_critair : 3 ; vehicle_history_teaser_owners : 2 ; vehicle_history_teaser_expertises : false ; vehicle_history_teaser_special_uses : false ; vehicle_history_teaser_atypical_operations : true ; vehicle_history_teaser_importations : true ; spare_parts_availability : Non renseignée | AP8: Voir | AQ8: 3281190008
A9: Alfa Romeo 156 2.5 V6 24V | B9: Alfa Romeo 156 2.5 V6 24V | E9: En vente | F9: 46301 | G9: 46301 | H9: 46310 | J9: =IF(OR(ISNUMBER(F9),ISNUMBER(G9)),IF(ISNUMBER(I9),I9,H9)-IF(ISNUMBER(F9),F9,G9),"") | K9: 7800 | L9: 7800 | M9: =IF(AND(ISNUMBER(K9),ISNUMBER(L9),K9>0),1-L9/K9,"") | N9: 0 | R9: =IF(AND(ISNUMBER(L9),ISNUMBER(P9),ISNUMBER(Q9)),L9/((P9+Q9)/2)-1,"") | T9: 213808 | U9: 2002 | V9: 03/2002 | W9: Essence | X9: Manuelle | Y9: 192 | Z9: 14 | AA9: Gris | AB9: 4 | AC9: Berline | AD9: Carnet d'entretien disponible, Factures disponibles, Véhicule non fumeur, Réparations utiles déjà faites | AE9: Première main | AF9: Particulier | AG9: Le Havre | AH9: 76620 | AI9: Seine-Maritime | AJ9: Haute-Normandie | AK9: 3 | AM9: Non | AN9: Bonjour , Avis aux passionnés et connaisseurs de la marque au trèfle ,Je me sépare à contre-cœur de mon Alfa Romeo 156 V6 2.5 de 2002, équipée du mythique moteur Arese (sonorité et comportement d'exception). Le véhicule a toujours été respecté, temps de chauffe et d'arrêt scrupuleusement appliqués, aucunes corrosion ! Dossier de factures monumentale. Énorme préparation esthétique et mécanique récente (plusieurs milliers d'euros investis cette année). ⚙️ TRAIN AVANT & CHÂSSIS (Refait à neuf en Ju | AO9: vehicle_technical_inspection_valid : Non ; Dommages : Traces d’usure normales ; Sellerie : Tout cuir ; Équipements intérieurs : Régulateur de vitesse, Sièges chauffants, Sièges en cuir ; vehicle_euro_emissions_standard : Euro 3 ; Permis : Avec permis ; Importé : false ; vehicle_history_teaser_critair : 3 ; vehicle_history_teaser_owners : 3 ; vehicle_history_teaser_expertises : false ; vehicle_history_teaser_special_uses : false ; vehicle_history_teaser_atypical_operations : false ; vehicle_history_teaser_importations : false | AP9: Voir | AQ9: 3283116401
A10: Alfa Romeo 156 2.5 V6 24V | B10: ALFA ROMEO 156 2.5 V6 24V BOÎTE AUTOMATIQUE 195cv COMPLÈTEMENT RÉVISÉ | E10: Partie | F10: 46244 | G10: 46244 | H10: 46296 | I10: 46310 | J10: =IF(OR(ISNUMBER(F10),ISNUMBER(G10)),IF(ISNUMBER(I10),I10,H10)-IF(ISNUMBER(F10),F10,G10),"") | K10: 4900 | L10: 4900 | M10: =IF(AND(ISNUMBER(K10),ISNUMBER(L10),K10>0),1-L10/K10,"") | N10: 0 | R10: =IF(AND(ISNUMBER(L10),ISNUMBER(P10),ISNUMBER(Q10)),L10/((P10+Q10)/2)-1,"") | T10: 147000 | U10: 2001 | W10: Essence | X10: Automatique | Y10: 195 | Z10: 10 | AA10: Ivoire | AB10: 5 | AC10: Berline | AF10: Pro | AG10: Blotzheim | AH10: 68730 | AI10: Haut-Rhin | AJ10: Alsace | AP10: Voir | AQ10: 3212500586
A11: Alfa Romeo 156 2.5 V6 24V | B11: Alfa Romeo 156 2.5 V6 24V | E11: Partie | F11: 46281 | G11: 46281 | H11: 46296 | I11: 46310 | J11: =IF(OR(ISNUMBER(F11),ISNUMBER(G11)),IF(ISNUMBER(I11),I11,H11)-IF(ISNUMBER(F11),F11,G11),"") | K11: 7000 | L11: 7000 | M11: =IF(AND(ISNUMBER(K11),ISNUMBER(L11),K11>0),1-L11/K11,"") | N11: 0 | R11: =IF(AND(ISNUMBER(L11),ISNUMBER(P11),ISNUMBER(Q11)),L11/((P11+Q11)/2)-1,"") | T11: 160000 | U11: 2002 | W11: Essence | X11: Automatique | Y11: 192 | Z11: 14 | AA11: Autre | AB11: 4 | AC11: Berline | AF11: Particulier | AG11: Marne-la-Vallée | AH11: 77186 | AI11: Seine-et-Marne | AJ11: Ile-de-France | AP11: Voir | AQ11: 3270896149
A12: BMW Z3 1.9i / 2.0i | B12: BMW z3 | E12: En vente | F12: 46300 | G12: 46300 | H12: 46310 | J12: =IF(OR(ISNUMBER(F12),ISNUMBER(G12)),IF(ISNUMBER(I12),I12,H12)-IF(ISNUMBER(F12),F12,G12),"") | K12: 7000 | L12: 7000 | M12: =IF(AND(ISNUMBER(K12),ISNUMBER(L12),K12>0),1-L12/K12,"") | N12: 0 | O12: 8000 | R12: =IF(AND(ISNUMBER(L12),ISNUMBER(P12),ISNUMBER(Q12)),L12/((P12+Q12)/2)-1,"") | T12: 158652 | U12: 1999 | V12: 08/1999 | W12: Essence | X12: Manuelle | Y12: 118 | Z12: 8 | AA12: Gris | AB12: 2 | AC12: Cabriolet | AF12: Particulier | AG12: Mallemort | AH12: 13370 | AI12: Bouches-du-Rhône | AJ12: Provence-Alpes-Côte d'Azur | AK12: 3 | AM12: Non | AN12: BMW z3 en bon état | AO12: Dommages : Bon état général ; Sellerie : Tissu ; Équipements intérieurs : Climatisation, Phares anti-brouillard, Sièges électriques ; Permis : Avec permis ; Importé : false | AP12: Voir | AQ12: 3211730689
A13: BMW Z3 1.9i / 2.0i | B13: BMW Z3 Roadster 1.8i 115ch SELLERIE NEUVE | C13: Z3 Roadster 1.8i 115ch | D13: Base | E13: En vente | F13: 46280 | G13: 46280 | H13: 46310 | J13: =IF(OR(ISNUMBER(F13),ISNUMBER(G13)),IF(ISNUMBER(I13),I13,H13)-IF(ISNUMBER(F13),F13,G13),"") | K13: 8990 | L13: 8990 | M13: =IF(AND(ISNUMBER(K13),ISNUMBER(L13),K13>0),1-L13/K13,"") | N13: 0 | R13: =IF(AND(ISNUMBER(L13),ISNUMBER(P13),ISNUMBER(Q13)),L13/((P13+Q13)/2)-1,"") | T13: 147000 | U13: 1996 | V13: 05/1996 | W13: Essence | X13: Manuelle | Y13: 116 | Z13: 9 | AA13: Gris | AB13: 2 | AF13: Pro | AG13: Abbeville | AH13: 80100 | AI13: Somme | AJ13: Picardie | AK13: 50 | AL13: Oui | AM13: Non | AN13: L'Agence TransakAuto ABBEVILLE, société spécialisée en courtage automobile, 1er réseau d'intermédiation automobile auprès des particuliers avec + de 180 agences en France depuis 2011, vous propose ce véhicule Bmw, Z3, Gris, 9 chevaux fiscaux, 2 portes, 147 000 km. ⚠ 🔦 Véhicule visible uniquement sur rdv à l'agence TransakAuto ABBEVILLE, du mardi au samedi de Lundi - Vendredi 10h - 19h Samedi 10h - 18h Véhicule en dépôt-vente [non stocké sur place]. Visible uniquement sur rendez-vous dans votre | AO13: Équipements intérieurs : Jantes en alliage, Sièges en cuir ; VO récent : false ; custom_ref : VO17964933 ; Importé : true ; vehicle_history_report_status : visible ; spare_parts_availability : Non renseignée | AP13: Voir | AQ13: 3237198765
A14: BMW Z3 1.9i / 2.0i | B14: BMW Z3 1.8L Roadster 115CV / CARROSSERIE NEUVE BMW / ENTRETIEN À JOUR / ÉTAT CONCOURS | C14: Z3 Roadster 1.8i 115ch | D14: Base | E14: En vente | F14: 46225 | G14: 46225 | H14: 46310 | J14: =IF(OR(ISNUMBER(F14),ISNUMBER(G14)),IF(ISNUMBER(I14),I14,H14)-IF(ISNUMBER(F14),F14,G14),"") | K14: 12990 | L14: 12990 | M14: =IF(AND(ISNUMBER(K14),ISNUMBER(L14),K14>0),1-L14/K14,"") | N14: 0 | O14: 13490 | R14: =IF(AND(ISNUMBER(L14),ISNUMBER(P14),ISNUMBER(Q14)),L14/((P14+Q14)/2)-1,"") | T14: 104800 | U14: 1997 | V14: 03/1997 | W14: Essence | X14: Manuelle | Y14: 116 | Z14: 7 | AA14: Noir | AB14: 2 | AC14: Cabriolet | AF14: Pro | AG14: Saint-Quentin | AH14: 02100 | AI14: Aisne | AJ14: Picardie | AK14: 39 | AL14: Oui | AM14: Non | AN14: L'Agence TransakAuto SAINT-QUENTIN, société spécialisée en courtage automobile, 1er réseau d'intermédiation automobile auprès des particuliers avec + de 180 agences en France depuis 2011, vous propose ce véhicule Bmw, Z3, Noir, 7 chevaux fiscaux, 2 portes, 104 800 km. 🚗 Véhicule visible uniquement sur rdv à l'agence TransakAuto SAINT-QUENTIN, du mardi au samedi de 10H00 à 18H00. Merci de nous appeler avant toute venue afin de vérifier sa disponibilité ainsi que les modalités de la visite. (Une | AO14: Équipements intérieurs : Climatisation, Jantes en alliage, Phares anti-brouillard, Sièges chauffants ; VO récent : false ; custom_ref : VO15721372 ; Importé : true ; vehicle_history_report_status : visible ; spare_parts_availability : Non renseignée | AP14: Voir | AQ14: 3237237759
A15: BMW Z3 1.9i / 2.0i | B15: BMW Z3 Roadster 1.8i 115ch GARANTIE 12 MOIS | C15: Z3 Roadster 1.8i 115ch | D15: Base | E15: En vente | F15: 46293 | G15: 46293 | H15: 46310 | J15: =IF(OR(ISNUMBER(F15),ISNUMBER(G15)),IF(ISNUMBER(I15),I15,H15)-IF(ISNUMBER(F15),F15,G15),"") | K15: 9990 | L15: 9990 | M15: =IF(AND(ISNUMBER(K15),ISNUMBER(L15),K15>0),1-L15/K15,"") | N15: 0 | R15: =IF(AND(ISNUMBER(L15),ISNUMBER(P15),ISNUMBER(Q15)),L15/((P15+Q15)/2)-1,"") | T15: 151000 | U15: 1999 | V15: 07/1999 | W15: Essence | X15: Manuelle | Y15: 116 | Z15: 7 | AA15: Bleu | AB15: 2 | AC15: Cabriolet | AF15: Pro | AG15: Béziers | AH15: 34500 | AI15: Hérault | AJ15: Languedoc-Roussillon | AK15: 13 | AL15: Oui | AM15: Non | AN15: BMW Z3 Roadster 1.8i 115ch GARANTIE 12 MOIS cabriolet, bleu, 7 cv, 2 portes, première mise en circulation le 01/07/1999, garantie 12 mois. Véhicule décrit avec ses équipements de série. Les équipements, les options et la version décrits sont sous réserve d erreurs de saisie. Ils doivent être vérifiés par l acheteur pendant l essai ou à la livraison. La garantie actuelle peut être étendue jusqu à 48 mois. Nous pouvons reprendre votre véhicule pour cet achat ou vous proposer un financement avec no | AO15: Équipements intérieurs : Jantes en alliage, Vitres électriques arrières ; Permis : Avec permis ; VO récent : false ; custom_ref : 64DV000520 ; Importé : true ; vehicle_history_report_status : visible ; spare_parts_availability : Non renseignée | AP15: Voir | AQ15: 3243864537
A16: BMW Z3 1.9i / 2.0i | B16: Bmw z3 | C16: Z3 Roadster 1.8i 115ch | D16: Base | E16: En vente | F16: 46309 | G16: 46309 | H16: 46310 | J16: =IF(OR(ISNUMBER(F16),ISNUMBER(G16)),IF(ISNUMBER(I16),I16,H16)-IF(ISNUMBER(F16),F16,G16),"") | K16: 12000 | L16: 12000 | M16: =IF(AND(ISNUMBER(K16),ISNUMBER(L16),K16>0),1-L16/K16,"") | N16: 0 | R16: =IF(AND(ISNUMBER(L16),ISNUMBER(P16),ISNUMBER(Q16)),L16/((P16+Q16)/2)-1,"") | T16: 65000 | U16: 1996 | V16: 10/1996 | W16: Essence | X16: Manuelle | Y16: 115 | Z16: 7 | AA16: Noir | AB16: 2 | AC16: Cabriolet | AF16: Particulier | AG16: Saint-Victoret | AH16: 13730 | AI16: Bouches-du-Rhône | AJ16: Provence-Alpes-Côte d'Azur | AK16: 3 | AM16: Non | AN16: Bmw Z3, faible, kilométrage en très bon état Peinture d'origine, prix 12 000 € | AO16: Dommages : Excellent état (proche du neuf) ; Sellerie : Tout cuir ; vehicle_euro_emissions_standard : Euro 2 ; Permis : Avec permis ; Importé : false | AP16: Voir | AQ16: 3246077665
